Workbook

Sheet Executive Summary
A1: CONTRACTOR BUSINESS PLAN
A2: Confidential Business Document
A4: ◆ COMPANY OVERVIEW
A6: Company Name: | C6: [Enter Company Name]
A7: Owner / Principal: | C7: [Enter Name]
A8: Business Structure: | C8: [LLC / S-Corp / Sole Proprietor]
A9: Date Established: | C9: [MM/YYYY]
A10: EIN / Tax ID: | C10: [XX-XXXXXXX]
A11: State License #: | C11: [Enter License Number]
A12: Address: | C12: [Street, City, State, ZIP]
A13: Phone / Email: | C13: [Phone] / [Email]
A15: ◆ MISSION STATEMENT
A16: [Write a clear, compelling mission statement that defines your purpose, values, and commitment to clients. Example: 'To deliver exceptional residential construction services with uncompromising quality, transparent communication, and on-time completion — building lasting relationships one project at a time.']
A20: ◆ SERVICES OFFERED
A22: Primary Service 1: | C22: [Describe service and typical project size]
A23: Primary Service 2: | C23: [Describe service and typical project size]
A24: Primary Service 3: | C24: [Describe service and typical project size]
A25: Secondary Service 1: | C25: [Describe service and typical project size]
A26: Secondary Service 2: | C26: [Describe service and typical project size]
A28: ◆ TARGET MARKET
A30: Customer Type: | C30: [Residential / Commercial / Both]
A31: Geographic Area: | C31: [City, County, or Region]
A32: Ideal Client Profile: | C32: [Income level, property type, project type]
A33: Market Size Estimate: | C33: [$X million in annual construction spending]
A35: ◆ COMPETITIVE ADVANTAGE
A37: Advantage 1: | C37: [What makes you different from competitors?]
A38: Advantage 2: | C38: [What makes you different from competitors?]
A39: Advantage 3: | C39: [What makes you different from competitors?]
A41: ◆ FINANCIAL PROJECTIONS SUMMARY
A42: Metric | B42: Year 1 | C42: Year 2 | D42: Year 3
A43: Total Revenue | B43: ='Financial Projections'!B36 | C43: ='Financial Projections'!C36 | D43: ='Financial Projections'!D36
A44: Total Expenses | B44: ='Financial Projections'!B37 | C44: ='Financial Projections'!C37 | D44: ='Financial Projections'!D37
A45: Net Profit | B45: ='Financial Projections'!B38 | C45: ='Financial Projections'!C38 | D45: ='Financial Projections'!D38
A46: Profit Margin | B46: ='Financial Projections'!B39 | C46: ='Financial Projections'!C39 | D46: ='Financial Projections'!D39

Sheet Financial Projections
A1: 3-YEAR FINANCIAL PROJECTIONS
A3: ◆ REVENUE ASSUMPTIONS
A4: Assumption | B4: Value | C4: Notes
A5: Avg. Project Value | B5: 15000 | C5: Typical contract size
A6: Projects per Month (Year 1) | B6: 3 | C6: Ramp-up period
A7: Projects per Month (Year 2) | B7: 5 | C7: Established pipeline
A8: Projects per Month (Year 3) | B8: 7 | C8: Growth phase
A9: Avg. Markup % | B9: 0.35 | C9: On cost of work
A10: Service Call Revenue/Mo | B10: 2000 | C10: Smaller repair jobs
A12: ◆ YEAR 1 — MONTHLY PROFIT & LOSS
A13: Category | B13: Jan | C13: Feb | D13: Mar | E13: Apr | F13: May | G13: Jun | H13: Jul | I13: Aug | J13: Sep | K13: Oct | L13: Nov | M13: Dec | N13: TOTAL
A14: REVENUE
A15: Project Revenue | B15: 25000 | C15: 30000 | D15: 35000 | E15: 40000 | F15: 45000 | G15: 50000 | H15: 50000 | I15: 55000 | J15: 55000 | K15: 50000 | L15: 45000 | M15: 40000 | N15: =SUM(B15:M15)
A16: Service Call Revenue | B16: 1500 | C16: 1500 | D16: 2000 | E16: 2000 | F16: 2500 | G16: 2500 | H16: 2500 | I16: 3000 | J16: 3000 | K16: 2500 | L16: 2000 | M16: 1500 | N16: =SUM(B16:M16)
A17: Other Revenue | B17: 0 | C17: 0 | D17: 500 | E17: 500 | F17: 500 | G17: 1000 | H17: 1000 | I17: 1000 | J17: 1000 | K17: 500 | L17: 500 | M17: 0 | N17: =SUM(B17:M17)
A18: TOTAL REVENUE | B18: =SUM(B15:B17) | C18: =SUM(C15:C17) | D18: =SUM(D15:D17) | E18: =SUM(E15:E17) | F18: =SUM(F15:F17) | G18: =SUM(G15:G17) | H18: =SUM(H15:H17) | I18: =SUM(I15:I17) | ... N18: =SUM(N15:N17)
A19: EXPENSES
A20: Cost of Goods Sold (Materials) | B20: 8000 | C20: 9500 | D20: 11000 | E20: 12500 | F20: 14000 | G20: 16000 | H20: 16000 | I20: 17500 | J20: 17500 | K20: 16000 | L20: 14000 | M20: 12500 | N20: =SUM(B20:M20)
A21: Labor (Crew) | B21: 6000 | C21: 6000 | D21: 7500 | E21: 7500 | F21: 9000 | G21: 9000 | H21: 9000 | I21: 10500 | J21: 10500 | K21: 9000 | L21: 7500 | M21: 6000 | N21: =SUM(B21:M21)
A22: Subcontractors | B22: 2000 | C22: 2500 | D22: 3000 | E22: 3500 | F22: 4000 | G22: 4500 | H22: 4500 | I22: 5000 | J22: 5000 | K22: 4000 | L22: 3000 | M22: 2000 | N22: =SUM(B22:M22)
A23: Vehicle Expenses | B23: 800 | C23: 800 | D23: 800 | E23: 800 | F23: 800 | G23: 800 | H23: 800 | I23: 800 | J23: 800 | K23: 800 | L23: 800 | M23: 800 | N23: =SUM(B23:M23)
A24: Insurance | B24: 500 | C24: 500 | D24: 500 | E24: 500 | F24: 500 | G24: 500 | H24: 500 | I24: 500 | J24: 500 | K24: 500 | L24: 500 | M24: 500 | N24: =SUM(B24:M24)
A25: Marketing & Advertising | B25: 1500 | C25: 1500 | D25: 1200 | E25: 1200 | F25: 1000 | G25: 1000 | H25: 1000 | I25: 800 | J25: 800 | K25: 1000 | L25: 1200 | M25: 1500 | N25: =SUM(B25:M25)
A26: Office & Admin | B26: 400 | C26: 400 | D26: 400 | E26: 400 | F26: 400 | G26: 400 | H26: 400 | I26: 400 | J26: 400 | K26: 400 | L26: 400 | M26: 400 | N26: =SUM(B26:M26)
A27: Tools & Equipment | B27: 500 | C27: 300 | D27: 300 | E27: 200 | F27: 200 | G27: 200 | H27: 200 | I27: 200 | J27: 200 | K27: 200 | L27: 300 | M27: 300 | N27: =SUM(B27:M27)
A28: Licenses & Permits | B28: 200 | C28: 0 | D28: 0 | E28: 0 | F28: 0 | G28: 0 | H28: 200 | I28: 0 | J28: 0 | K28: 0 | L28: 0 | M28: 200 | N28: =SUM(B28:M28)
A29: Professional Services | B29: 300 | C29: 300 | D29: 300 | E29: 300 | F29: 300 | G29: 300 | H29: 300 | I29: 300 | J29: 300 | K29: 300 | L29: 300 | M29: 300 | N29: =SUM(B29:M29)
A30: TOTAL EXPENSES | B30: =SUM(B20:B29) | C30: =SUM(C20:C29) | D30: =SUM(D20:D29) | E30: =SUM(E20:E29) | F30: =SUM(F20:F29) | G30: =SUM(G20:G29) | H30: =SUM(H20:H29) | I30: =SUM(I20:I29) | ... N30: =SUM(N20:N29)
A31: NET PROFIT / (LOSS) | B31: =B18-B30 | C31: =C18-C30 | D31: =D18-D30 | E31: =E18-E30 | F31: =F18-F30 | G31: =G18-G30 | H31: =H18-H30 | I31: =I18-I30 | ... N31: =N18-N30
A32: PROFIT MARGIN | B32: =IF(B18=0,0,B31/B18) | C32: =IF(C18=0,0,C31/C18) | D32: =IF(D18=0,0,D31/D18) | E32: =IF(E18=0,0,E31/E18) | F32: =IF(F18=0,0,F31/F18) | G32: =IF(G18=0,0,G31/G18) | H32: =IF(H18=0,0,H31/H18) | I32: =IF(I18=0,0,I31/I18) | ... N32: =IF(N18=0,0,N31/N18)
A34: ◆ 3-YEAR ANNUAL SUMMARY
A35: Category | B35: Year 1 | C35: Year 2 | D35: Year 3
A36: Total Revenue | B36: =N18 | C36: =N18*1.4 | D36: =N18*1.9
A37: Total Expenses | B37: =N30 | C37: =N30*1.25 | D37: =N30*1.5
A38: Net Profit | B38: =B36-B37 | C38: =C36-C37 | D38: =D36-D37
A39: Profit Margin | B39: =IF(B36=0,0,B38/B36) | C39: =IF(C36=0,0,C38/C36) | D39: =IF(D36=0,0,D38/D36)
A41: ◆ BREAK-EVEN ANALYSIS
A43: Monthly Fixed Costs | B43: 5000 | C43: [Sum of fixed monthly expenses]
A44: Avg. Revenue per Project | B44: 15000 | C44: [From assumptions above]
A45: Avg. Variable Cost per Project | B45: 9500 | C45: [Materials + labor + subs per project]
...

Sheet Startup Costs
A1: STARTUP COST CHECKLIST
A3: Item | B3: Estimated Cost | C3: Actual Cost | D3: Variance | E3: Notes
A4: ◆ TOOLS & EQUIPMENT
A5: Power Tools (drills, saws, etc.) | B5: 3000 | D5: =C5-B5
A6: Hand Tools | B6: 1500 | D6: =C6-B6
A7: Ladders & Scaffolding | B7: 1200 | D7: =C7-B7
A8: Safety Equipment (PPE) | B8: 800 | D8: =C8-B8
A9: Specialty Tools | B9: 2000 | D9: =C9-B9
A10: Tool Storage / Trailer | B10: 3500 | D10: =C10-B10
A11: Subtotal | B11: =SUM(B5:B10) | C11: =SUM(C5:C10) | D11: =SUM(D5:D10)
A12: ◆ VEHICLES
A13: Work Truck / Van | B13: 35000 | D13: =C13-B13
A14: Vehicle Wrap / Signage | B14: 2500 | D14: =C14-B14
A15: Trailer | B15: 5000 | D15: =C15-B15
A16: GPS / Fleet Tracking | B16: 500 | D16: =C16-B16
A17: Subtotal | B17: =SUM(B13:B16) | C17: =SUM(C13:C16) | D17: =SUM(D13:D16)
A18: ◆ INSURANCE
A19: General Liability Insurance | B19: 2500 | D19: =C19-B19
A20: Workers' Compensation | B20: 3000 | D20: =C20-B20
A21: Commercial Auto Insurance | B21: 2000 | D21: =C21-B21
A22: Professional Liability (E&O) | B22: 1500 | D22: =C22-B22
A23: Builders Risk / Inland Marine | B23: 1200 | D23: =C23-B23
A24: Umbrella Policy | B24: 800 | D24: =C24-B24
A25: Subtotal | B25: =SUM(B19:B24) | C25: =SUM(C19:C24) | D25: =SUM(D19:D24)
A26: ◆ LICENSING & PERMITS
A27: State Contractor License | B27: 500 | D27: =C27-B27
A28: Local Business License | B28: 200 | D28: =C28-B28
A29: Trade Certifications | B29: 1000 | D29: =C29-B29
A30: Bond (if required) | B30: 1500 | D30: =C30-B30
A31: EPA / Environmental Permits | B31: 300 | D31: =C31-B31
A32: Subtotal | B32: =SUM(B27:B31) | C32: =SUM(C27:C31) | D32: =SUM(D27:D31)
A33: ◆ MARKETING & BRANDING
A34: Logo & Brand Design | B34: 1500 | D34: =C34-B34
A35: Website Development | B35: 3000 | D35: =C35-B35
A36: Business Cards & Print | B36: 500 | D36: =C36-B36
A37: Online Advertising (initial) | B37: 2000 | D37: =C37-B37
A38: Yard Signs / Job Site Signs | B38: 600 | D38: =C38-B38
A39: Social Media Setup | B39: 500 | D39: =C39-B39
A40: Google Business Profile Setup | B40: 0 | D40: =C40-B40
A41: Subtotal | B41: =SUM(B34:B40) | C41: =SUM(C34:C40) | D41: =SUM(D34:D40)
...

Sheet Marketing Plan
A1: MARKETING PLAN
A3: ◆ MARKETING CHANNELS & BUDGET
A4: Channel | B4: Strategy | C4: Monthly Budget | D4: Annual Budget | E4: Expected Leads/Mo | F4: Cost per Lead | G4: Timeline | H4: KPI | I4: Priority
A5: Google Ads | B5: Local search campaigns | C5: 1500 | D5: =C5*12 | E5: 20 | F5: =C5/E5 | G5: Month 1+ | H5: Leads, CPA | I5: HIGH
A6: SEO / Website | B6: Content + local SEO | C6: 500 | D6: =C6*12 | E6: 15 | F6: =C6/E6 | G6: Month 1+ | H6: Organic traffic | I6: HIGH
A7: Google Business | B7: Reviews + posts | C7: 0 | D7: =C7*12 | E7: 10 | F7: =IF(E7=0,0,C7/E7) | G7: Month 1+ | H7: Reviews, calls | I7: HIGH
A8: Facebook/Instagram | B8: Before/after posts, ads | C8: 800 | D8: =C8*12 | E8: 8 | F8: =C8/E8 | G8: Month 1+ | H8: Engagement | I8: MED
A9: Nextdoor | B9: Community engagement | C9: 200 | D9: =C9*12 | E9: 5 | F9: =C9/E9 | G9: Month 2+ | H9: Recommendations | I9: MED
A10: Yard Signs | B10: Job site signage | C10: 100 | D10: =C10*12 | E10: 3 | F10: =C10/E10 | G10: Month 1+ | H10: Calls from signs | I10: MED
A11: Referral Program | B11: Incentive for referrals | C11: 300 | D11: =C11*12 | E11: 4 | F11: =C11/E11 | G11: Month 3+ | H11: Referral rate | I11: HIGH
A12: Direct Mail | B12: Targeted postcards | C12: 500 | D12: =C12*12 | E12: 3 | F12: =C12/E12 | G12: Quarterly | H12: Response rate | I12: LOW
A13: Home Shows/Events | B13: Local event booths | C13: 200 | D13: =C13*12 | E13: 5 | F13: =C13/E13 | G13: Seasonal | H13: Contacts | I13: LOW
A14: Vehicle Wrap | B14: Mobile advertising | C14: 100 | D14: =C14*12 | E14: 2 | F14: =C14/E14 | G14: Month 1+ | H14: Brand awareness | I14: MED
A15: TOTAL | C15: =SUM(C5:C14) | D15: =SUM(D5:D14) | E15: =SUM(E5:E14) | F15: =IF(E15=0,0,C15/E15)
A17: ◆ MARKETING GOALS & KPIs
A18: Metric | B18: Month 1 | C18: Month 3 | D18: Month 6 | E18: Month 12 | F18: Notes
A19: Website Visitors/Month | B19: 200 | C19: 500 | D19: 1500 | E19: 3000 | F19: Track via Google Analytics
A20: Leads Generated/Month | B20: 10 | C20: 25 | D20: 50 | E20: 75 | F20: Phone + form + email
A21: Conversion Rate | B21: 5% | C21: 8% | D21: 12% | E21: 15% | F21: Leads → signed contracts
A22: New Customers/Month | B22: 1 | C22: 2 | D22: 6 | E22: 11 | F22: Signed contracts
A23: Google Reviews | B23: 5 | C23: 15 | D23: 30 | E23: 60 | F23: Target: 4.8+ avg rating
A24: Social Media Followers | B24: 50 | C24: 200 | D24: 500 | E24: 1000 | F24: All platforms combined
A25: Revenue from Marketing | B25: 15000 | C25: 30000 | D25: 90000 | E25: 165000 | F25: Attributed revenue

Sheet Operations
A1: OPERATIONS PLAN
A3: ◆ CREW PLANNING
A4: Role | B4: Name | C4: Hourly Rate | D4: Weekly Hours | E4: Weekly Cost | F4: Annual Cost | G4: Start Date | H4: Status | I4: Notes
A5: Owner / Lead | B5: [Your Name] | C5: 45 | D5: 50 | E5: =C5*D5 | F5: =E5*52 | G5: [Date] | H5: Active
A6: Foreman | B6: [TBD] | C6: 35 | D6: 45 | E6: =C6*D6 | F6: =E6*52 | G6: [Month 3] | H6: Planned
A7: Journeyman 1 | B7: [TBD] | C7: 28 | D7: 40 | E7: =C7*D7 | F7: =E7*52 | G7: [Month 2] | H7: Planned
A8: Journeyman 2 | B8: [TBD] | C8: 28 | D8: 40 | E8: =C8*D8 | F8: =E8*52 | G8: [Month 6] | H8: Planned
A9: Apprentice | B9: [TBD] | C9: 18 | D9: 40 | E9: =C9*D9 | F9: =E9*52 | G9: [Month 4] | H9: Planned
A10: Laborer 1 | B10: [TBD] | C10: 16 | D10: 40 | E10: =C10*D10 | F10: =E10*52 | G10: [Month 1] | H10: Planned
A11: Laborer 2 | B11: [TBD] | C11: 16 | D11: 40 | E11: =C11*D11 | F11: =E11*52 | G11: [Month 6] | H11: Planned
A12: Office Manager | B12: [TBD] | C12: 22 | D12: 30 | E12: =C12*D12 | F12: =E12*52 | G12: [Month 9] | H12: Planned | I12: Part-time
A14: ◆ EQUIPMENT LIST
A15: Equipment | B15: Qty | C15: Unit Cost | D15: Total Cost | E15: Condition | F15: Replace By | G15: Priority
A16: Circular Saw | B16: 2 | C16: 350 | D16: =B16*C16 | E16: New | F16: 2029 | G16: Essential
A17: Miter Saw (12") | B17: 1 | C17: 600 | D17: =B17*C17 | E17: New | F17: 2030 | G17: Essential
A18: Table Saw (Portable) | B18: 1 | C18: 800 | D18: =B18*C18 | E18: New | F18: 2030 | G18: Essential
A19: Drill/Driver Set | B19: 4 | C19: 200 | D19: =B19*C19 | E19: New | F19: 2028 | G19: Essential
A20: Impact Driver Set | B20: 3 | C20: 250 | D20: =B20*C20 | E20: New | F20: 2028 | G20: Essential
A21: Air Compressor | B21: 1 | C21: 500 | D21: =B21*C21 | E21: New | F21: 2030 | G21: Essential
A22: Nail Gun (Framing) | B22: 2 | C22: 350 | D22: =B22*C22 | E22: New | F22: 2029 | G22: Essential
A23: Nail Gun (Finish) | B23: 2 | C23: 300 | D23: =B23*C23 | E23: New | F23: 2029 | G23: Essential
A24: Laser Level | B24: 1 | C24: 400 | D24: =B24*C24 | E24: New | F24: 2031 | G24: Essential
A25: Generator (7500W) | B25: 1 | C25: 1200 | D25: =B25*C25 | E25: New | F25: 2032 | G25: Important
A26: Concrete Mixer | B26: 1 | C26: 800 | D26: =B26*C26 | E26: Good | F26: 2030 | G26: Important
A27: Scaffolding Set | B27: 1 | C27: 1500 | D27: =B27*C27 | E27: New | F27: 2032 | G27: Essential
... A30: First Aid Kits | B30: 2 | C30: 75 | D30: =B30*C30 | E30: New | F30: Annual | G30: Essential
A32: ◆ VEHICLE FLEET
A33: Vehicle | B33: Year/Make/Model | C33: License Plate | D33: Mileage | E33: Monthly Payment | F33: Insurance/Mo | G33: Fuel/Mo | H33: Total/Mo
A34: Truck 1 (Primary) | B34: [Year Make Model] | C34: [Plate #] | D34: 0 | E34: 650 | F34: 250 | G34: 400 | H34: =SUM(E34:G34)
A35: Truck 2 (Crew) | B35: [Year Make Model] | C35: [Plate #] | D35: 0 | E35: 550 | F35: 200 | G35: 350 | H35: =SUM(E35:G35)
A36: Trailer | B36: [Year Make Model] | C36: [Plate #] | D36: N/A | E36: 200 | F36: 50 | G36: 0 | H36: =SUM(E36:G36)
A38: ◆ INSURANCE REQUIREMENTS CHECKLIST
A39: Insurance Type | B39: Required? | C39: Provider | D39: Policy # | E39: Annual Premium | F39: Coverage Amount | G39: Renewal Date | H39: Status
A40: General Liability | B40: YES | E40: 2500 | F40: $1M/$2M | H40: ☐ Active
A41: Workers' Compensation | B41: YES | E41: 3000 | F41: Per state req. | H41: ☐ Active
A42: Commercial Auto | B42: YES | E42: 2400 | F42: $1M combined | H42: ☐ Active
A43: Professional Liability | B43: Recommended | E43: 1500 | F43: $1M/$2M | H43: ☐ Pending
A44: Builders Risk | B44: Per project | E44: 1200 | F44: Project value | H44: ☐ Pending
A45: Umbrella Policy | B45: Recommended | E45: 800 | F45: $2M+ | H45: ☐ Pending
A46: Commercial Property | B46: If applicable | E46: 1000 | F46: Contents value | H46: ☐ Pending
...
